<mujoco model="rod">

    <asset>
        <texture file="../../textures/steel-scratched.png" type="cube" name="steel-metal"/>
        <material name="smetal" reflectance="1.0" shininess="1.0" specular="1.0" texrepeat="1 1" texture="steel-metal" texuniform="true"/>
    </asset>

    <actuator>
        <!-- Physical limits of the actuator. -->
        <motor ctrllimited="true" ctrlrange="-80.0 80.0" joint="joint1" name="torq_j1"/>
    </actuator>

    <worldbody>
        <body name="link0" pos="0 0 0">

            <body name="base"/>

            <body name="link1" pos="0 0 0.2">
                <inertial pos="0 0 0" mass="1.0" diaginertia="0.0208895833333 0.0208895833333 0.0001125"/>
                <joint name="joint1" pos="0 0 -0.2" axis="0 1 0" limited="true" range="-2.8973 2.8973" damping="0.1"/>
                <geom type="cylinder" size="0.01 0.2" contype="0" conaffinity="0" group="1" name="link1_visual" material="smetal"/>
                <geom type="cylinder" size="0.01 0.2" group="0" name="link1_collision"/>

                <!-- 槽 -->
                <body name="slot" pos="0 0 0.2">
                    <geom pos="-0.02 0 0.01" type="box" size="0.005 0.01 0.01" contype="0" conaffinity="0" group="1" name="slot1_visual" material="smetal"/>
                    <geom pos="-0.02 0 0.01" type="box" size="0.005 0.01 0.01" group="0" name="slot1_collision"/>

                    <geom pos="0.02 0 0.01" type="box" size="0.005 0.01 0.01" contype="0" conaffinity="0" group="1" name="slot2_visual" material="smetal"/>
                    <geom pos="0.02 0 0.01" type="box" size="0.005 0.01 0.01" group="0" name="slot2_collision"/>

                    <geom pos="0 0 0.005" type="box" size="0.02 0.01 0.005" contype="0" conaffinity="0" group="1" name="slot3_visual" material="smetal"/>
                    <geom pos="0 0 0.005" type="box" size="0.02 0.01 0.005" group="0" name="slot3_collision"/>

                    <site name="rodtop" pos="0 0 0.0225"  size="0.01 0.01 0.01" rgba="0 0 1 1" type="sphere" group="1"/>
                </body>
            </body>

        </body>
    </worldbody>
</mujoco>
